Traceback (most recent call last):
  File "/data/users/roota5351/.local/lib/python3.9/site-packages/transformers/utils/import_utils.py", line 1778, in _get_module
    return importlib.import_module("." + module_name, self.__name__)
  File "/usr/lib64/python3.9/importlib/__init__.py", line 127, in import_module
    return _bootstrap._gcd_import(name[level:], package, level)
  File "<frozen importlib._bootstrap>", line 1030, in _gcd_import
  File "<frozen importlib._bootstrap>", line 1007, in _find_and_load
  File "<frozen importlib._bootstrap>", line 986, in _find_and_load_unlocked
  File "<frozen importlib._bootstrap>", line 680, in _load_unlocked
  File "<frozen importlib._bootstrap_external>", line 850, in exec_module
  File "<frozen importlib._bootstrap>", line 228, in _call_with_frames_removed
  File "/data/users/roota5351/.local/lib/python3.9/site-packages/transformers/models/llama/modeling_llama.py", line 41, in <module>
    from ...modeling_utils import PreTrainedModel
  File "/data/users/roota5351/.local/lib/python3.9/site-packages/transformers/modeling_utils.py", line 48, in <module>
    from .loss.loss_utils import LOSS_MAPPING
  File "/data/users/roota5351/.local/lib/python3.9/site-packages/transformers/loss/loss_utils.py", line 19, in <module>
    from .loss_deformable_detr import DeformableDetrForObjectDetectionLoss, DeformableDetrForSegmentationLoss
  File "/data/users/roota5351/.local/lib/python3.9/site-packages/transformers/loss/loss_deformable_detr.py", line 4, in <module>
    from ..image_transforms import center_to_corners_format
  File "/data/users/roota5351/.local/lib/python3.9/site-packages/transformers/image_transforms.py", line 22, in <module>
    from .image_utils import (
  File "/data/users/roota5351/.local/lib/python3.9/site-packages/transformers/image_utils.py", line 58, in <module>
    from torchvision.transforms import InterpolationMode
  File "/data/users/roota5351/.local/lib/python3.9/site-packages/torchvision/__init__.py", line 10, in <module>
    from torchvision import _meta_registrations, datasets, io, models, ops, transforms, utils  # usort:skip
  File "/data/users/roota5351/.local/lib/python3.9/site-packages/torchvision/models/__init__.py", line 2, in <module>
    from .convnext import *
  File "/data/users/roota5351/.local/lib/python3.9/site-packages/torchvision/models/convnext.py", line 8, in <module>
    from ..ops.misc import Conv2dNormActivation, Permute
  File "/data/users/roota5351/.local/lib/python3.9/site-packages/torchvision/ops/__init__.py", line 23, in <module>
    from .poolers import MultiScaleRoIAlign
  File "/data/users/roota5351/.local/lib/python3.9/site-packages/torchvision/ops/poolers.py", line 10, in <module>
    from .roi_align import roi_align
  File "/data/users/roota5351/.local/lib/python3.9/site-packages/torchvision/ops/roi_align.py", line 7, in <module>
    from torch._dynamo.utils import is_compile_supported
  File "/data/users/roota5351/.local/lib/python3.9/site-packages/torch/_dynamo/__init__.py", line 3, in <module>
    from . import convert_frame, eval_frame, resume_execution
  File "/data/users/roota5351/.local/lib/python3.9/site-packages/torch/_dynamo/convert_frame.py", line 30, in <module>
    from torch._dynamo.distributed import get_compile_pg
  File "/data/users/roota5351/.local/lib/python3.9/site-packages/torch/_dynamo/distributed.py", line 5, in <module>
    from . import config
  File "/data/users/roota5351/.local/lib/python3.9/site-packages/torch/_dynamo/config.py", line 399, in <module>
    debug_dir_root = default_debug_dir_root()
  File "/data/users/roota5351/.local/lib/python3.9/site-packages/torch/_dynamo/config.py", line 395, in default_debug_dir_root
    return os.path.join(os.getcwd(), "torch_compile_debug")
FileNotFoundError: [Errno 2] No such file or directory

The above exception was the direct cause of the following exception:

Traceback (most recent call last):
  File "/data/groups/classes/2024/fall/cs426/group_5/SchSearch/scholary-search/./py_scripts/dload_llama_weights.py", line 7, in <module>
  File "/data/users/roota5351/.local/lib/python3.9/site-packages/transformers/models/auto/auto_factory.py", line 563, in from_pretrained
    model_class = _get_model_class(config, cls._model_mapping)
  File "/data/users/roota5351/.local/lib/python3.9/site-packages/transformers/models/auto/auto_factory.py", line 388, in _get_model_class
    supported_models = model_mapping[type(config)]
  File "/data/users/roota5351/.local/lib/python3.9/site-packages/transformers/models/auto/auto_factory.py", line 763, in __getitem__
    return self._load_attr_from_module(model_type, model_name)
  File "/data/users/roota5351/.local/lib/python3.9/site-packages/transformers/models/auto/auto_factory.py", line 777, in _load_attr_from_module
    return getattribute_from_module(self._modules[module_name], attr)
  File "/data/users/roota5351/.local/lib/python3.9/site-packages/transformers/models/auto/auto_factory.py", line 693, in getattribute_from_module
    if hasattr(module, attr):
  File "/data/users/roota5351/.local/lib/python3.9/site-packages/transformers/utils/import_utils.py", line 1766, in __getattr__
    module = self._get_module(self._class_to_module[name])
  File "/data/users/roota5351/.local/lib/python3.9/site-packages/transformers/utils/import_utils.py", line 1780, in _get_module
    raise RuntimeError(
RuntimeError: Failed to import transformers.models.llama.modeling_llama because of the following error (look up to see its traceback):
[Errno 2] No such file or directory
slurmstepd: error: run_script_as_user: couldn't change working dir to /data/groups/classes/2024/fall/cs426/group_5/SchSearch/scholary-search: No such file or directory
